Workbook
Name A25300000: #REF!

Sheet FORMATO ACTUALIZACIÓN DATOS
A1: SECRETARÍA DE EDUCACIÓN DE BOGOTÁ
A2: OFICINA DE TESORERÍA Y CONTABILIDAD
A4: FORMULARIO DE ACTUALIZACIÓN DE DATOS PARA PERSONAS NATURALES HONORARIOS Y SERVICIOS PERSONALES ART.103 DEL ET
A8: IDENTIFICACIÓN
A10: Número de Identificación Tributaria (NIT): | P10: DV | R10: Tipo de Contribuyente | AC10: Tipo de Documento | AP10: =IF(AA11=1,"Número de Identificación del Contacto","Número de Identificación") -> Número de Identificación
R11: PERSONA NATURAL | AA11: =IFERROR(VLOOKUP(R11,'Validador- Datos'!K16:L18,2,0),"") -> 2 | AN11: =IFERROR(VLOOKUP(AC11,'Validador- Datos'!K1:M14,2,0),"")
A13: =CLEAN(TRIM(A11)) | P13: =+A13-AP13 -> #VALUE! | R13: =IFERROR(IF(AA11=1,1,IF(P13=0,1,0)),0) -> 0 | AA13: =IF(AA11=1,"J",IF(AA11=2,"N","")) -> N | AN13: =IFERROR(VLOOKUP(AN11,'Validador- Datos'!L2:M14,2,0),"") | AP13: =IFERROR(VALUE(CLEAN(TRIM(AP11))),"")
A14: =CONCATENATE(A11,B11,C11,D11,E11,F11,G11,H11,I11,J11,K11,L11,M11,N11) | AP14: =CONCATENATE(AP11,AQ11,AR11,AS11,AT11,AU11,AV11,AW11,AX11,AY11,AZ11,BA11,BB11,BC11)
A15: Primer Apellido | I15: Segundo Apellido | Q15: Primer Nombre | Y15: Otros Nombres | AI15: Nombre Completo
AI16: =CONCATENATE(UPPER(A16)," ",UPPER(I16)," ",UPPER(Q16)," ",UPPER((Y16)))
A18: Es Usted pensionado o ya adquirio los derechos para serlo. | P18: SI | R18: NO | U18: DIRECCIÓN REPORTADA EN EL RUT | AS18: =IF(AC18=0,"",AC18)
A20: País | T20: Departamento (Solo para país Colombia) | AM20: Municipio (Solo para País Colombia)
P21: =IFERROR(VLOOKUP(A21,'Validador- Datos'!T1:U249,2,0),"") | AI21: =IFERROR(VLOOKUP(T21,'Validador- Datos'!W1:X36,2,0),"") | BB21: =IFERROR(VLOOKUP(AM21,'Validador- Datos'!AK1:AL126,2,0),"")
A23: Correo Electrónico | AG23: Teléfono 1 | AQ23: Teléfono 2
A24: cacsa@cascsa.com
AG26: =CLEAN(TRIM(CONCATENATE(AG24,AH24,AI24,AJ24,AK24,AL24,AM24,AN24,AO24,AP24))) | AQ26: =CONCATENATE(AR24,AS24,AT24,AU24,AV24,AW24,AX24,AY24,AZ24,BA24,BB24,BC24)
A28: SISTEMA AUTOMÁTICO DE PAGOS
A30: Banco | Q30: Sucursal | Z30: Tipo Cuenta | AH30: Identificación Titular | AN30: Cuenta Bancaria
M31: =IFERROR(VLOOKUP(A31,bancos[],4,0),"") | AE31: =IFERROR(VLOOKUP(Z31,TIPOCUENTA[],2,0),"") | AH31: =CONCATENATE(A14,"-",P11) -> -
AN32: =TRIM(CONCATENATE(AN31,AO31,AP31,AQ31,AR31,AS31,AT31,AU31,AV31,AW31,AX31,AY31,AZ31,BA31,BB31,BC31))
A36: CLASIFICACIÓN Y RESPONSABILIDADES TRIBUTARIAS
A38: Actividad Económica RUT | X38: Actividad Económica RIT | AU38: Régimen IVA
F39: =IF(A40="","",(IFERROR(VLOOKUP(A40,CIIU[],2,0),"Actividad economica NO existe - por favor verificar"))) | AD39: =IF(X40="","",(IFERROR(VLOOKUP(X40,RIT[],3,0),"Actividad economica NO existe - por favor verificar"))) | AQ39: Tarifa x Mil | BC39: =IFERROR(VLOOKUP(AU39,REGIMEN[],2,0),"")
A40: =CONCATENATE(A39,B39,C39,D39) | X40: =IFERROR(VALUE(CLEAN(TRIM(CONCATENATE(X39,Y39,Z39,AA39,AB39)))),"") | AQ40: =IF(AD39="Actividad economica NO existe o no aplica para el tipo de Contribuyente - por favor verificar","",IF(X40="","",IFERROR(VLOOKUP(X40,'Validador- Datos'!AS2:AV553,4,0),"Actividad economica NO existe - por favor verificar")))
A42: DATOS DEL CONTRATO
A44: No contrato | F44: Año Contrato | K44: Valor Total Contrato | W44: Duración (DÍAS) | AC44: Fecha Acta de Inicio ( aaaa/mm/dd) | AN44: Fecha terminación Contrato ( aaaa/mm/dd) | AY44: Cesión
W46: ='Validador- Datos'!L28
F47: =CONCATENATE(F46,G46,H46,I46)
A49: Valor Pago Mensual según Contrato | N49: CRP 1 | Q49: FECHA CRP 1 aaaa/mm/dd | V49: RP VIGENCIA FUTURA | AC49: CRP 2 | AF49: FECHA CRP 2 aaaa/mm/dd | AN49: CRP 3 | AQ49: FECHA CRP 3 aaaa/mm/dd | AX49: Código Actividad ARL
A52: Área Funcional de la SED | J52: Nombre Interventor Contrato | S52: Cargo Interventor Contrato | Z52: Nombre Operativo | AH52: Identificación Operativo | AP52: Valor del Contrato sin IVA | AW52: =ROUND(IF(AU39="RESPONSABLE IVA",(K46/1.19),IF('Validador- Datos'!BM2>='Validador- Datos'!BL2,'Validador- Datos'!BN2,K46)),0) -> 0
H53: =_xlfn.IFNA(VLOOKUP(A53,ÁREA[#All],2,FALSE),"") | AP53: Valor del IVA del Contrato | AW53: =ROUND(IF(K46<>AW52,AW52*0.19,0),0) -> 0
A58: CERTIFICACIÓN APLICACIÓN RETENCIÓN EN LA FUENTE ARTÍCULOS 383 Y 387 DEL ESTATUTO TRIBUTARIO
A59: FAVOR RESPONDA LAS SIGUIENTES PREGUNTAS:
A61: C1 | C61: 1. ¿Mis ingresos del año gravable 2025 fueron superiores a $ 73´323.600 equivalentes a 1.400 UVT? | AZ61: SI | BB61: NO
A64: C2 | C64: 2. ¿Estoy obligada(o) a declarar Impuesto de Renta para el año 2025? (Ver artículo 592 del Estatuto Tributario) | AZ64: SI | BB64: NO
A67: C3 | C67: 3.¿Pertenezco al Régimen Simple de Tributación -SIMPLE? (LEY 2010 DE 2019) SI LA DIAN NO ME HA CATALOGADO COMO SIMPLE COLOCO LA "X" EN NO | AZ67: SI | BB67: NO
A70: C4 | C70: 4. El trabajador empleará costos y gastos de acuerdo al Decreto 2231 de 2023 | AZ70: SI | BB70: NO
C73: ='Validador- Datos'!BE23 -> REVISE SU INFORMACIÓN TRIBUTARIA
A75: DISMINUCIÓN DE LA BASE DE RETENCIÓN EN LA FUENTE
S76: CERTIFICADOS EXPEDIDOS CON CORTE AL 31 DE DICIEMBRE DE: | AN76: =+'FORMATO DEDUCCIONES'!W16 -> 2025
...

Sheet INSTRUCTIVO ACTUALIZACION DATOS
A6: I. OBJETIVO
A7: Establecer las instrucciones para el correcto diligenciamiento del Formato de Actualización de Terceros – Persona Natural, con el fin de registrar y actualizar la información personal, tributaria, bancaria y contractual de los terceros vinculados a la Secretaría de Educación del Distrito, garantizando la confiabilidad de los datos utilizados en los procesos administrativos, financieros y contables de la entidad.
A9: II. ALCANCE
A10: Este instructivo aplica a todas las personas naturales que mantengan o vayan a mantener relación contractual o administrativa con la Secretaría de Educación del Distrito, tales como contratistas, prestadores de servicios que requieran registrarse o actualizar su información en la entidad. Comprende el diligenciamiento del formato, la entrega de los soportes correspondientes y la verificación de la información por parte de las áreas responsables.
A11: III. RESPONSABLE
A13: Contratista (Persona Natural) • Diligenciar completamente el formato de Excel con la información actualizada. •Aportar la documentación soporte requerida • Garantizar la veracidad de la información suministrada. Área Financiera / Tesorería / Grupo de actualizaciones de terceros • Revisar la información registrada. • Validar los datos tributarios y bancarios frente a soportes recibidos • Utilizar la información para incluirla en el sistema Apoteosys para la liquidación de los pagos.
A15: IV. FRECUENCIA
A17: La actualización del formato debe realizarse: • Al inicio del contrato. • Cuando exista cambio en la información tributaria o bancaria. • Cuando la Secretaría de Educación del Distrito lo solicite.
A19: V. INSTRUCCIONES GENERALES DE DILIGENCIAMIENTO
A20: 1. Diligenciar el formato únicamente en las celdas habilitadas (color amarillo). 2. No modificar la estructura del archivo, fórmulas y celdas protegidas. 3. La información registrada debe coincidir con la contenida en el RUT y RIT vigente, así como la certificación bancaria. 4. Verificar que los datos sean correctos antes de remitir el archivo. 5. Adjuntar los soportes requeridos actualizados y la certificación bancaria.
A22: INFORMACIÓN GENERAL DEL TERCERO En esta sección se deben registrar los datos de identificación del tercero objeto de pago: • Número de Identificación Tributaria (NIT): registrar el número de identificación tributaria correspondiente según el RUT. • DV: diligenciar el dígito de verificación indicado en el RUT. • Tipo de Contribuyente: "Persona Natural", se encuentra preestablecido, no registrar información en este campo. • Tipo de Documento: indicar el tipo de identificación del tercero de acuerdo con lista desplegable • Número de Identificación: registrar el número del documento sin puntos ni espacios, sin dígito de verificación del RUT. Datos personales • Primer Apellido • Segundo Apellido • Primer Nombre • Otros Nombres • Nombre Completo: Campo formulado, no registrar información en este campo. Información pensional • Marcar SI o NO en la pregunta: "¿Es usted pensionado o ya adquirió los derechos para serlo?", una vez haya sido validado por la supervisión del contrato.
A23: DIRECCIÓN REGISTRADA EN EL RUT Registrar la información de ubicación según lo reportado en el Registro Único Tributario (RUT): • Dirección • País • Departamento (solo si el país es Colombia) • Municipio (solo si el país es Colombia) Datos de contacto • Correo electrónico • Teléfono 1, dato obligatorio, si no tiene telefono fijo por favor diligenciar 0 • Teléfono 2, número de celular
... A32: El presente formado debe presentarse en formato PDF debidamente FIRMADO por el tercero objeto de actualización de información

Sheet FORMATO DEDUCCIONES
A1: SECRETARÍA DE EDUCACIÓN DE BOGOTÁ
A3: OFICINA DE TESORERÍA Y CONTABILIDAD
A5: FORMULARIO DISMINUCIÓN DE LA BASE DE RETENCIÓN EN LA FUENTE PERSONAS NATURALES OPS
A7: FECHA SOLICITUD
A9: DATOS DEL TERCERO
A11: NOMBRES Y APELLIDOS DEL TERCERO | J11: ='FORMATO ACTUALIZACIÓN DATOS'!AI16
A13: CÉDULA DE CIUDADANÍA No. | G13: ='FORMATO ACTUALIZACIÓN DATOS'!AP11 -> 0 | P13: No CONTRATO | S13: =IF('FORMATO ACTUALIZACIÓN DATOS'!A46,'FORMATO ACTUALIZACIÓN DATOS'!A46," ") | W13: AÑO CONTRATO | Z13: ='FORMATO ACTUALIZACIÓN DATOS'!F47
A15: FECHA EN LA QUE SE DILIGENCIA EL FORMATO: | W15: =TODAY() -> 46204
A16: AÑO FISCAL PARA EL QUE APLICARA EL BENEFICIO : | W16: ='Validador- Datos'!BK12 -> 2025
A18: POR DEPENDIENTES
B20: DATOS DEL DEPENDIENTE
B21: NOMBRES Y APELLIDOS | O21: No DE IDENTIFICACIÓN | U21: EDAD | W21: PARENTESCO
B24: SELECCIONE EL MOTIVO DE LA SOLICITUD:
AC25: =VALUE(LEFT(B25,1)) -> #VALUE!
B28: VALOR MENSUAL | M28: =IFERROR('Validador- Datos'!BM7,"") -> 0
B30: Como soporte se anexa la siguiente documentación:
B31: =IFERROR(VLOOKUP(AC25,P128:Q132,2,0),"")
A33: POR PAGOS EFECTUADOS POR CONTRATOS DE SALUD NO POS
B35: NOMBRE DE LA ENTIDAD
B37: NIT ENTIDAD | U37: VALOR TOTAL PAGADO
Q39: VALOR MENSUAL | W39: ='Validador- Datos'!BM8 -> 0
B40: FECHA EXPEDICIÓN CERTIFICADO | R40: FECHA CORTE DEL CERTIFICADO
B41: =+B30 -> Como soporte se anexa la siguiente documentación:
B42: =IF(H35="","",AD44)
A44: POR PAGO DE CRÉDITOS HIPOTECARIOS | AD44: =CONCATENATE("CERTIFICADO EXPEDIDO POR ",H35," A NOMBRE DE ",J11," TITULAR DEL CONTRATO ") -> CERTIFICADO EXPEDIDO POR A NOMBRE DE TITULAR DEL CONTRATO
B46: NOMBRE DE LA ENTIDAD
B48: NIT ENTIDAD | U48: VALOR TOTAL INTERES PAGADO
Q50: VALOR MENSUAL | W50: =IF(L54="",'Validador- Datos'!BM9,'Validador- Datos'!BM9/L54) -> 0
B52: FECHA EXPEDICIÓN CERTIFICADO | R52: FECHA CORTE DEL CERTIFICADO
B54: CANTIDAD DE TITULARES DEL CRÉDITO
B56: =+B41 -> Como soporte se anexa la siguiente documentación:
B57: =IF(H46="","",AD59)
AD59: =CONCATENATE("CERTIFICADO EXPEDIDO POR ",H46," A NOMBRE DE ",,J11, " TITULAR DEL CREDITO ") -> CERTIFICADO EXPEDIDO POR A NOMBRE DE TITULAR DEL CREDITO
B60: Declaro que asumo íntegramente la responsabilidad por la veracidad de esta información, la cual puede ser comprobada por la entidad cuando lo considere.; por lo anterior cualquier falsedad en que se incurra podrá ser sancionada.
B62: No de Folios anexos
B68: =+J11
B70: Con la firma del presente formulario certificó la veracidad de la información en él consignada y autorizó a la Secretaria de Educación de Bogotá su uso para la liquidación del FURC y la actualización de la información de las bases de datos de la Entidad, en especial la de Apoteosys y la información reportada a la DIAN. Al firmar este documento, autorizo de manera previa, expresa e informada a la Secretaría de Educación del Distrito para que realice el tratamiento de mis datos personales aquí suministrados. Esta información será utilizada con fines de actualización de información del tercero, conforme a la Ley 1581 de 2012 y a la Política de Tratamiento de Datos disponible en www.educacionbogota.gov.co. Como titular, tengo derecho a conocer, actualizar, rectificar y solicitar la supresión de mis datos, así como a presentar quejas ante la Superintendencia de Industria y Comercio
B71: =+G13 -> 0 | Z71: 13-IF-016
Z72: V.1.
H84: 2018
...

Sheet INSTRUCTIVO DEDUCCIONES
A6: I. OBJETIVO
A7: Establecer las instrucciones para el correcto diligenciamiento del formato mediante el cual las personas naturales vinculadas mediante contrato reportan las deducciones tributarias aplicables para efectos fiscales, conforme a la normatividad vigente en Colombia y lineamientos establecidos por la Dirección de Impuestos y Aduanas Nacionales (DIAN).
A9: II. ALCANCE
A10: Este instructivo aplica a todas las personas naturales que tengan relación contractual o administrativa con la Secretaría de Educación del Distrito, tales como contratistas, prestadores de servicios que requieran registrarse o actualizar su información en la entidad. Comprende el diligenciamiento del formato, la entrega de los soportes correspondientes y la verificación de la información por parte de las áreas responsables.
A12: III. RESPONSABLE
A14: Contratista (Persona Natural) • Diligenciar completamente el formato de Excel con la información actualizada. •Aportar la documentación soporte requerida • Garantizar la veracidad de la información suministrada. Área Financiera / Tesorería / Grupo de actualizaciones de terceros • Revisar la información registrada. • Validar los datos tributarios y bancarios frente a los soportes recibidos • Utilizar la información para incluirla en el sistema Apoteosys para la liquidación de los pagos.
A16: IV. FRECUENCIA
A18: La actualización del formato debe realizarse: • Cuando exista cambio en la información tributaria o bancaria, o por cambio en la normatividad vigente y/o por ordenamiento de la Secretaría de Educación del Distrito, cuando haya lugar
A20: V. INSTRUCCIONES GENERALES DE DILIGENCIAMIENTO
A21: 1.Diligenciar el formato únicamente en las celdas habilitadas (color amarillo). 2. El formato debe diligenciarse con información veraz. 3. Los valores deben registrarse en pesos colombianos (COP). 4. Todos los campos deben completarse de acuerdo con los certificados o documentos soporte. 5. Los documentos anexos deben ser legibles y corresponder al mismo año fiscal reportado. 6. El formato debe presentarse junto con los soportes que acrediten las deducciones solicitadas.
A23: VI.DILIGENCIAMIENTO DEL FORMATO
A25: DATOS DEL TERCERO Todos los campos son datos formulados que vienen del diligenciamiento de la hoja Formato actualizacion de datos.
... A32: El diligenciamiento del presente formato implica que el declarante certifica que la información suministrada es veraz, que los documentos anexos corresponden a la realidad y que las deducciones solicitadas cumplen con los requisitos establecidos en la normativa tributaria vigente.

Sheet Validador- Datos
A1: VALIDADOR | H1: LETRAS | I1: NUMERO | K1: TIPO DE DOCUMENTO | L1: COD_DIAN | M1: COD_APOT | O1: NOMENCLATURA | P1: COD | Q1: CUADRANTE | R1: BIS | T1: PAIS | U1: Código | W1: DPTO | X1: COD_DEPTO | Z1: Cod busqueda | AA1: =+'FORMATO ACTUALIZACIÓN DATOS'!AI21 | AB1: DPTO | AC1: COD_DEPTO | AD1: cod_dep ciu | AE1: No | AF1: NOM_MPIO | AG1: COD_MPIO | AK1: NOM_MPIO | AL1: COD_MPIO | AN1: Denominación social de la Entidad | AO1: Denominación abreviada de la entidad | AP1: NIT | AQ1: Cod | AS1: CÓDIGO | AT1: AGRUPACIÓN | AU1: D E S C R I P C I Ó N | AV1: AÑO 2024 | AX1: CLASIFICACIÓN INDUSTRIAL INTERNACIONAL UNIFORME, REVISIÓN 4 ADAPTADA PARA COLOMBIA CIIU Rev. 4 A.C. | AY1: DESCRIPCIÓN | BA1: DESCRIPCIÓN DE ACTIVIDAD ECONÓMICA FINAL ARL | BB1: condigo completo | BC1: TARIFA | BE1: CODIFICACIÓN | BI1: AÑO | BJ1: UVT | BK1: LIMITE | BL1: LIMITE PESOS | BM1: VALOR CONTRATO | BN1: CONTRATO SIN IVA | BO1: IVA CONTRATO
A2: No. | B2: Val. | C2: Descripción | D2: Formula | H2: A | I2: 0 | K2: Registro civil | L2: 11 | M2: OTI | O2: Autopista | P2: AUT | Q2: SUR | R2: BIS | T2: COLOMBIA | U2: 169 | W2: Bogotá D.C | X2: 11 | AB2: Antioquia | AC2: 05 | AD2: =CONCATENATE(AC2,"-",AE2) -> 05-1 | AE2: 1 | AF2: MEDELLÍN | AG2: 001 | AI2: 1 | AJ2: =CONCATENATE($AA$1,"-",AI2) -> -1 | AK2: =IFERROR(VLOOKUP(AJ2,$AD$2:$AG$1120,3,0),"") | AL2: =IFERROR(VLOOKUP(AJ2,$AD$2:$AG$1120,4,0),"") | AN2: Banco Popular | AO2: Banco Popular | AQ2: 2 | AS2: 111 | AU2: Cultivo de cereales (excepto arroz), legumbres y semillas oleaginosas | AV2: 0 | AX2: 0010 | AY2: Asalariados | BA2: EMPRESAS DEDICADAS A ACTIVIDADES DE SERVICIOS, AGRÍCOLAS Y GANADEROS, EXCEPTO LAS ACTIVIDADES VETERINARIAS INCLUYE EL ALMACÉN Y/O DEPOSITO DE CAFÉ | BB2: 114001 | BE2: =IF('FORMATO ACTUALIZACIÓN DATOS'!AU39="RESPONSABLE IVA","C",IF('FORMATO ACTUALIZACIÓN DATOS'!AU39="NO RESPONSABLE IVA","S","ERROR")) -> ERROR | BF2: RESPONSABLE DE IVA =S | BG2: NO RESPONSABLE DE IVA=C | BI2: 2026 | BJ2: 52374 | BK2: 4000 | BL2: =BK2*BJ2 -> 209496000 | BM2: ='FORMATO ACTUALIZACIÓN DATOS'!K46 -> 0 | BN2: =ROUND(BM2/1.19,) -> 0 | BO2: =ROUND(BN2*0.19,) -> 0 | BP2: =BN2+BO2 -> 0
A3: 1 | B3: =IF('FORMATO ACTUALIZACIÓN DATOS'!A13="",0,1) -> 0 | C3: Número de Identificación Tributaria (NIT) | D3: =IF(B3=0,CONCATENATE(" - ",C3,""),"") -> - Número de Identificación Tributaria (NIT) | H3: B | I3: 1 | K3: Tarjeta de identidad | L3: 12 | M3: TI | O3: Avenida | P3: AV | Q3: ESTE | R3: BIS A | T3: AFGANISTAN | U3: 013 | W3: Amazonas | X3: 91 | AB3: Antioquia | AC3: 05 | AD3: =CONCATENATE(AC3,"-",AE3) -> 05-2 | AE3: =IF(AB3=AB2,1+AE2,1) -> 2 | AF3: ABEJORRAL | AG3: 002 | AI3: 2 | AJ3: =CONCATENATE($AA$1,"-",AI3) -> -2 | AK3: =IFERROR(VLOOKUP(AJ3,$AD$2:$AG$1120,3,0),"") | AL3: =IFERROR(VLOOKUP(AJ3,$AD$2:$AG$1120,4,0),"") | AN3: BBVA Colombia | AO3: BBVA Colombia | AQ3: 13 | AS3: 112 | AU3: Cultivo de arroz | AV3: 0 | AX3: 0081 | AY3: Personas Naturales sin Actividad Económica | BA3: Tejeduria de productos textiles, incluye produccion de hilados, tejidos y similares a mano o con equipo no motorizado. | BB3: 1131201 | BE3: =IF(OR('FORMATO ACTUALIZACIÓN DATOS'!BA61="X",'FORMATO ACTUALIZACIÓN DATOS'!BA64="X")=TRUE,"VERDADERO","FALSO") -> FALSO | BF3: ingresos del año gravable 2025 fueron superiores a $73,323,600 O declara Impuesto de Renta
A4: 2 | B4: =IF('FORMATO ACTUALIZACIÓN DATOS'!P11="",0,1) -> 0 | C4: DV | D4: =IF(B4=0,CONCATENATE(" - ",C4,""),"") -> - DV | H4: C | I4: 2 | K4: Cédula de ciudadanía | L4: 13 | M4: CC | O4: Avenida Calle | P4: AC | T4: ALBANIA | U4: 017 | W4: Antioquia | X4: 05 | AB4: Antioquia | AC4: 05 | AD4: =CONCATENATE(AC4,"-",AE4) -> 05-3 | AE4: =IF(AB4=AB3,1+AE3,1) -> 3 | AF4: ABRIAQUÍ | AG4: 004 | AI4: 3 | AJ4: =CONCATENATE($AA$1,"-",AI4) -> -3 | AK4: =IFERROR(VLOOKUP(AJ4,$AD$2:$AG$1120,3,0),"") | AL4: =IFERROR(VLOOKUP(AJ4,$AD$2:$AG$1120,4,0),"") | AN4: Banco Davivienda S.A. | AO4: Banco Davivienda S.A. | AQ4: 51 | AS4: 113 | AU4: Cultivo de hortalizas, raíces y tubérculos | AV4: 0 | AX4: 0082 | AY4: Personas Naturales Subsidiadas por Terceros | BA4: Tejeduria de productos textiles, incluye la fabricacion de articulos confeccionados de materiales textiles, a partir de tejidos de produccion propia a mano o con equipo no motorizado. | BB4: 1131202 | BE4: =IF(OR('FORMATO ACTUALIZACIÓN DATOS'!BA61="X",'FORMATO ACTUALIZACIÓN DATOS'!BA64="X")=TRUE,"SI","NO") -> NO | BF4: ingresos del año gravable 2025 fueron superiores a $73,323,600 O declara Impuesto de Renta
A5: 3 | B5: =IF('FORMATO ACTUALIZACIÓN DATOS'!R11="",0,1) -> 1 | C5: Tipo de Contribuyente | D5: =IF(B5=0,CONCATENATE(" - ",C5,""),"") | H5: D | I5: 3 | K5: Certificado de la Registraduría para sucesiones ilíquidas de personas naturales | L5: 14 | M5: OTI | O5: Avenida Carrera | P5: AK | T5: ALEMANIA | U5: 023 | W5: Arauca | X5: 81 | AB5: Antioquia | AC5: 05 | AD5: =CONCATENATE(AC5,"-",AE5) -> 05-4 | AE5: =IF(AB5=AB4,1+AE4,1) -> 4 | AF5: ALEJANDRÍA | AG5: 021 | AI5: 4 | AJ5: =CONCATENATE($AA$1,"-",AI5) -> -4 | AK5: =IFERROR(VLOOKUP(AJ5,$AD$2:$AG$1120,3,0),"") | AL5: =IFERROR(VLOOKUP(AJ5,$AD$2:$AG$1120,4,0),"") | AN5: Banco de Bogotá | AO5: Banco de Bogotá | AQ5: 1 | AS5: 114 | AU5: Cultivo de tabaco | AV5: 0 | AX5: 0090 | AY5: Rentistas de Capital, solo para personas naturales. | BA5: Fabricacion de tapetes y alfombras para pisos, incluye la fabricacion de tapices, esteras, tapetes a mano o con equipo no motorizado. | BB5: 1139301 | BE5: =IF(OR('FORMATO ACTUALIZACIÓN DATOS'!BC61="X",'FORMATO ACTUALIZACIÓN DATOS'!BC64="X")=TRUE,"SI","NO") -> NO | BF5: ingresos del año gravable 2025 NO fueron superiores a $73,323,600 O NO declara Impuesto de Renta
A6: 4 | B6: =IF('FORMATO ACTUALIZACIÓN DATOS'!AC11="",0,1) -> 0 | C6: Tipo de Documento | D6: =IF(B6=0,CONCATENATE(" - ",C6,""),"") -> - Tipo de Documento | H6: E | I6: 4 | K6: Tipo de documento que identifica una sucesión ilíquida, expedido por la Notaria o Juzgado | L6: 15 | M6: OTI | O6: Boulevard | P6: BL | T6: ANDORRA | U6: 037 | W6: SanAndres | X6: 88 | AB6: Antioquia | AC6: 05 | AD6: =CONCATENATE(AC6,"-",AE6) -> 05-5 | AE6: =IF(AB6=AB5,1+AE5,1) -> 5 | AF6: AMAGÁ | AG6: 030 | AI6: 5 | AJ6: =CONCATENATE($AA$1,"-",AI6) -> -5 | AK6: =IFERROR(VLOOKUP(AJ6,$AD$2:$AG$1120,3,0),"") | AL6: =IFERROR(VLOOKUP(AJ6,$AD$2:$AG$1120,4,0),"") | AN6: Bancolombia SA | AO6: Bancolombia SA | AQ6: 7 | AS6: 115 | AU6: Cultivo de plantas textiles | AV6: 0 | AX6: 0111 | AY6: Cultivo de cereales (excepto arroz), legumbres y semillas oleaginosas. | BA6: Confeccion de prendas de vestir, excepto prendas de piel, incluye pequeños talleres, confeccion de prendas de vestir sobre medidas y/o en serie, sombreros y gorros, incluso de piel, confeccion de ropa y confeccion de partes de los productos mencionados. | BB6: 1141001 | BE6: =IF(AND('FORMATO ACTUALIZACIÓN DATOS'!BA61="X",'FORMATO ACTUALIZACIÓN DATOS'!BC61="X",'FORMATO ACTUALIZACIÓN DATOS'!BA64="X",'FORMATO ACTUALIZACIÓN DATOS'!BC64="x")=TRUE,"SI","NO") -> NO | BF6: se llena las dos primeras preguntas de manera incongruente llenando todas las opciones | BI6: DESCRIPCIÓN | BJ6: VALOR MENSUAL | BK6: autorizado | BL6: MAXIMO ley | BM6: max. Aplicar mensual | BN6: Max Anual | BO6: max. Aplicar
A7: 5 | B7: =IF(E7=1,1,IF('FORMATO ACTUALIZACIÓN DATOS'!AP13="",0,1)) -> 0 | C7: Número de Identificación | D7: =IF(B7=0,CONCATENATE(" - ",C7,""),"") -> - Número de Identificación | E7: ='FORMATO ACTUALIZACIÓN DATOS'!AA11 -> 2 | H7: F | I7: 5 | K7: Tarjeta de extranjería | L7: 21 | M7: OTI | O7: Calle | P7: CL | T7: ANGOLA | U7: 040 | W7: Atlántico | X7: 08 | AB7: Antioquia | AC7: 05 | AD7: =CONCATENATE(AC7,"-",AE7) -> 05-6 | AE7: =IF(AB7=AB6,1+AE6,1) -> 6 | AF7: AMALFI | AG7: 031 | AI7: 6 | AJ7: =CONCATENATE($AA$1,"-",AI7) -> -6 | AK7: =IFERROR(VLOOKUP(AJ7,$AD$2:$AG$1120,3,0),"") | AL7: =IFERROR(VLOOKUP(AJ7,$AD$2:$AG$1120,4,0),"") | AN7: Banco de Occidente | AO7: Banco de Occidente | AQ7: 23 | AS7: 119 | AU7: Otros cultivos transitorios n.c.p. | AV7: 0 | AX7: 0112 | AY7: Cultivo de arroz. | BA7: TEJEDURA DE PRODUCTOS TEXTILES: HACE REFERENCIA A EMPRESAS DEDICADAS A PRODUCIR HILADOS, TEJIDOS Y SIMILARES A MANO O CON EQUIPO NO MOTORIZADO | BB7: 1172001 | BE7: =IF(AND('FORMATO ACTUALIZACIÓN DATOS'!BA61="",,'FORMATO ACTUALIZACIÓN DATOS'!BA64="")=TRUE,"SI","NO") -> NO | BI7: DEPENDIENTES | BJ7: ='FORMATO ACTUALIZACIÓN DATOS'!A50 -> 0 | BK7: =BJ7*0.1 -> 0 | BL7: {=Valor_con_IVA[UVT]*32} -> 1675968 | BM7: =MIN(BK7,BL7) -> 0 | BN7: {=384*Valor_con_IVA[UVT]} -> 20111616
A8: 5.1 | B8: ='FORMATO ACTUALIZACIÓN DATOS'!R13 -> 0 | C8: Verificar el Número de Identificación | D8: =IF(B8=0,CONCATENATE(" - ",C8,""),"") -> - Verificar el Número de Identificación | H8: G | I8: 6 | K8: Cédula de extranjería | L8: 22 | M8: CE | O8: Carrera | P8: CR | T8: ANGUILLA | U8: 041 | W8: Bogotá D.C | X8: 11 | AB8: Antioquia | AC8: 05 | AD8: =CONCATENATE(AC8,"-",AE8) -> 05-7 | AE8: =IF(AB8=AB7,1+AE7,1) -> 7 | AF8: ANDES | AG8: 034 | AI8: 7 | AJ8: =CONCATENATE($AA$1,"-",AI8) -> -7 | AK8: =IFERROR(VLOOKUP(AJ8,$AD$2:$AG$1120,3,0),"") | AL8: =IFERROR(VLOOKUP(AJ8,$AD$2:$AG$1120,4,0),"") | AN8: Banco Agrario | AO8: Banco Agrario | AQ8: 40 | AS8: 121 | AU8: Cultivo de frutas tropicales y subtropicales | AV8: 0 | AX8: 0113 | AY8: Cultivo de hortalizas, raíces y tubérculos. | BA8: FABRICACIÓN DE TAPICES Y ALFOMBRAS PARA PISOS HACE REFERENCIA A EMPRESAS DEDICADAS A LA FABRICACIÓN DE TAPETES Y SIMILARES A MANO O CON EQUIPO NO MOTORIZADO | BB8: 1174201 | BE8: =IF(AND('FORMATO ACTUALIZACIÓN DATOS'!BC61="",'FORMATO ACTUALIZACIÓN DATOS'!BC64="")=TRUE,"SI","NO") -> SI | BF8: se marco que SI las dos primeras preguntas | BI8: NO POS | BJ8: =BJ7 -> 0 | BK8: {=16*12*Valor_con_IVA[UVT]} -> 10055808 | BL8: =BK8/12 -> 837984 | BM8: =MIN(BL8,'FORMATO DEDUCCIONES'!Y37/12) -> 0 | BO8: =BL9/12 -> 436450
A9: 6 | B9: =IF(E7=1,1,IF('FORMATO ACTUALIZACIÓN DATOS'!A16="",0,1)) -> 0 | C9: Primer Apellido | D9: =IF(B9=0,CONCATENATE(" - ",C9,""),"") -> - Primer Apellido | H9: H | I9: 7 | K9: Identificación de extranjeros diferente al NIT asignado DIAN | L9: 33 | M9: OTI | O9: Carretera | P9: CRT | T9: ANTIGUA Y BARBUDA | U9: 043 | W9: Bolívar | X9: 13 | AB9: Antioquia | AC9: 05 | AD9: =CONCATENATE(AC9,"-",AE9) -> 05-8 | AE9: =IF(AB9=AB8,1+AE8,1) -> 8 | AF9: ANGELÓPOLIS | AG9: 036 | AI9: 8 | AJ9: =CONCATENATE($AA$1,"-",AI9) -> -8 | AK9: =IFERROR(VLOOKUP(AJ9,$AD$2:$AG$1120,3,0),"") | AL9: =IFERROR(VLOOKUP(AJ9,$AD$2:$AG$1120,4,0),"") | AN9: Banco Davibank | AO9: Banco Davibank | AQ9: 19 | AS9: 122 | AU9: Cultivo de plátano y banano | AV9: 0 | AX9: 0114 | AY9: Cultivo de tabaco. | BA9: FABRICACIÓN DE PRENDAS DE VESTIR, EXCEPTO PRENDAS: PEQUEÑOS TALLERES DE MODAS, SASTRERÍAS, SOMBREROS, CONFECCIONES DE ROPA | BB9: 1181001 | BE9: =CONCATENATE('FORMATO ACTUALIZACIÓN DATOS'!BA61,'FORMATO ACTUALIZACIÓN DATOS'!BC61) | BF9: si hay 2 X´s se llena de manera erronea | BI9: INTERESES | BJ9: =BJ8 -> 0 | BK9: ='FORMATO DEDUCCIONES'!Y48/12 -> 0 | BL9: {=100*Valor_con_IVA[UVT]} -> 5237400 | BM9: =MIN(BK9,BL9) -> 0
A10: 7 | B10: =IF(E7=1,1,IF('FORMATO ACTUALIZACIÓN DATOS'!Q16="",0,1)) -> 0 | C10: Primer Nombre | D10: =IF(B10=0,CONCATENATE(" - ",C10,""),"") -> - Primer Nombre | H10: I | I10: 8 | K10: Pasaporte | L10: 41 | M10: OTI | O10: Circunvalar | P10: CV | T10: ANTILLAS HOLANDESAS | U10: 047 | W10: Boyacá | X10: 15 | AB10: Antioquia | AC10: 05 | AD10: =CONCATENATE(AC10,"-",AE10) -> 05-9 | AE10: =IF(AB10=AB9,1+AE9,1) -> 9 | AF10: ANGOSTURA | AG10: 038 | AI10: 9 | AJ10: =CONCATENATE($AA$1,"-",AI10) -> -9 | AK10: =IFERROR(VLOOKUP(AJ10,$AD$2:$AG$1120,3,0),"") | AL10: =IFERROR(VLOOKUP(AJ10,$AD$2:$AG$1120,4,0),"") | AN10: Banco Caja Social BCSC SA | AO10: Banco Caja Social BCSC SA | AQ10: 32 | AS10: 123 | AU10: Cultivo de café | AV10: 0 | AX10: 0115 | AY10: Cultivo de plantas textiles. | BA10: Comercio comercio al por mayor y al por menor de motocicletas de sus partes, piezas y accesorios; incluye pequeños establecimientos comerciales que se dedican al mantenimiento y reparacion de motocicletas de pequeña potencia o ciclomotores y trineos motorizados, nuevos y usados, sus partes, piezas y accesorios. | BB10: 1454101 | BE10: =LEN(BE9) -> 0
A11: 8 | B11: =IF(AND('FORMATO ACTUALIZACIÓN DATOS'!Q18="x",'FORMATO ACTUALIZACIÓN DATOS'!S18="x"),0,IF(OR('FORMATO ACTUALIZACIÓN DATOS'!Q18="x",'FORMATO ACTUALIZACIÓN DATOS'!S18="x"),1,0)) -> 0 | C11: Indicar SI es o NO pensionado | D11: =IF(B11=0,CONCATENATE(" - ",C11,""),"") -> - Indicar SI es o NO pensionado | H11: J | I11: 9 | K11: Documento de identificación extranjero | L11: 42 | M11: OTI | O11: Circular | P11: CV | T11: ARABIA SAUDITA | U11: 053 | W11: Caldas | X11: 17 | AB11: Antioquia | AC11: 05 | AD11: =CONCATENATE(AC11,"-",AE11) -> 05-10 | AE11: =IF(AB11=AB10,1+AE10,1) -> 10 | AF11: ANORÍ | AG11: 040 | AI11: 10 | AJ11: =CONCATENATE($AA$1,"-",AI11) -> -10 | AK11: =IFERROR(VLOOKUP(AJ11,$AD$2:$AG$1120,3,0),"") | AL11: =IFERROR(VLOOKUP(AJ11,$AD$2:$AG$1120,4,0),"") | AN11: Banco GNB Sudameris | AO11: Banco GNB Sudameris | AQ11: 12 | AS11: 124 | AU11: Cultivo de caña de azúcar | AV11: 0 | AX11: 0119 | AY11: Otros cultivos transitorios n.c.p. | BA11: Mantenimiento y reparacion de motocicletas y de sus partes y piezas, incluye las actividades de mantenimiento y reparacion de motocicletas y trineos motorizados, asi como de todo tipo de partes y piezas de los mismos. | BB11: 1454201 | BE11: =CONCATENATE('FORMATO ACTUALIZACIÓN DATOS'!BA64,'FORMATO ACTUALIZACIÓN DATOS'!BC64) | BF11: si hay 2 X´s se llena de manera erronea
A12: 9 | B12: =IF('FORMATO ACTUALIZACIÓN DATOS'!AC18="",0,1) -> 0 | C12: Indique la Dirección tal y como aparece en el RUT | D12: =IF(B12=0,CONCATENATE(" - ",C12,""),"") -> - Indique la Dirección tal y como aparece en el RUT | H12: K | K12: Sin identificación del exterior o para uso definido por la DIAN. | L12: 43 | M12: OTI | O12: Diagonal | P12: DG | T12: ARGELIA | U12: 059 | W12: Caquetá | X12: 18 | AB12: Antioquia | AC12: 05 | AD12: =CONCATENATE(AC12,"-",AE12) -> 05-11 | AE12: =IF(AB12=AB11,1+AE11,1) -> 11 | AF12: SANTAFÉ DE ANTIOQUIA | AG12: 042 | AI12: 11 | AJ12: =CONCATENATE($AA$1,"-",AI12) -> -11 | AK12: =IFERROR(VLOOKUP(AJ12,$AD$2:$AG$1120,3,0),"") | AL12: =IFERROR(VLOOKUP(AJ12,$AD$2:$AG$1120,4,0),"") | AN12: Citibank | AO12: Citibank | AQ12: 9 | AS12: 125 | AU12: Cultivo de flor de corte | AV12: 0 | AX12: 0121 | AY12: Cultivo de frutas tropicales y subtropicales. | BA12: Comercio al por mayor a cambio de una retribucion o por contrata, incluye la a venta de: materias primas agropecuarias, animales vivos y aves muertas. | BB12: 1461001 | BE12: =LEN(BE11) -> 0 | BI12: ='FORMATO DEDUCCIONES'!W15 -> 46204 | BJ12: =IF(BI13<BI12,BJ13,IF(BI12<BI13,2021,2022)) -> 2025 | BK12: =MIN(BJ12:BJ16) -> 2025
A13: 10 | B13: =IF('FORMATO ACTUALIZACIÓN DATOS'!AI21="",0,1) -> 0 | C13: País | D13: =IF(B13=0,CONCATENATE(" - ",C13,""),"") -> - País | H13: L | K13: Documento de Identificación extranjero Persona Jurídica | L13: 44 | M13: OTI | O13: Kilómetro | P13: KM | T13: ARGENTINA | U13: 063 | W13: Casanare | X13: 85 | AB13: Antioquia | AC13: 05 | AD13: =CONCATENATE(AC13,"-",AE13) -> 05-12 | AE13: =IF(AB13=AB12,1+AE12,1) -> 12 | AF13: ANZA | AG13: 044 | AI13: 12 | AJ13: =CONCATENATE($AA$1,"-",AI13) -> -12 | AK13: =IFERROR(VLOOKUP(AJ13,$AD$2:$AG$1120,3,0),"") | AL13: =IFERROR(VLOOKUP(AJ13,$AD$2:$AG$1120,4,0),"") | AN13: Banco Santander de Negocios Colombia S.A. | AO13: Banco Santander de Negocios Colombia S.A. | AQ13: 65 | AS13: 126 | AU13: Cultivo de palma para aceite (palma africana) y otros frutos oleaginosos | AV13: 0 | AX13: 0122 | AY13: Cultivo de plátano y banano. | BA13: Comercio al por mayor a cambio de una retribucion o por contrata, incluye agentes dedicados a la venta de: materias primas agropecuarias, bebidas y tabaco; productos semiacabados textiles, prendas de vestir, pieles, casas de subasta al por mayor y comisionistas y otros mayoristas que comercian en nombre y por cuenta de terceros; actividades de las personas que ponen en contacto a vendedores y compradores y realizan transacciones comerciales en nombre de un ordenante (comprador), incluidas las realizadas por internet. | BB13: 1461002 | BE13: =BE12+BE10 -> 0 | BI13: 45017 | BJ13: =IF(BI14<BI12,BJ14,IF(BI12<BI14,2022,2023)) -> 2025
A14: 11 | B14: =IF(OR('FORMATO ACTUALIZACIÓN DATOS'!P21="169",'FORMATO ACTUALIZACIÓN DATOS'!P21=""),IF('FORMATO ACTUALIZACIÓN DATOS'!T21="",0,1),1) -> 0 | C14: Departamento | D14: =IF(B14=0,CONCATENATE(" - ",C14,""),"") -> - Departamento | H14: M | K14: Carné Diplomático: Documento expedido por el Ministerio de Relaciones | L14: 46 | M14: OTI | O14: Pasaje | P14: PJ | T14: ARMENIA | U14: 026 | W14: Cauca | X14: 19 | AB14: Antioquia | AC14: 05 | AD14: =CONCATENATE(AC14,"-",AE14) -> 05-13 | AE14: =IF(AB14=AB13,1+AE13,1) -> 13 | AF14: APARTADÓ | AG14: 045 | AI14: 13 | AJ14: =CONCATENATE($AA$1,"-",AI14) -> -13 | AK14: =IFERROR(VLOOKUP(AJ14,$AD$2:$AG$1120,3,0),"") | AL14: =IFERROR(VLOOKUP(AJ14,$AD$2:$AG$1120,4,0),"") | AN14: Banco AV Villas | AO14: Banco AV Villas | AQ14: 52 | AS14: 127 | AU14: Cultivo de plantas con las que se prepararan bebidas | AV14: 0 | AX14: 0123 | AY14: Cultivo de café. | BA14: Comercio al por mayor de materias primas agropecuarias; animales vivos, incluye granos y semillas, frutos oleaginosos, flores, plantas y sus partes, tabaco en bruto, cafe pergamino (incluida la pasilla de produccion), cafe trillado. | BB14: 1462001 | BE14: =IF(BE13=2,IF(AND(BE6="NO",BE7="NO")=TRUE,IF(BE3="VERDADERO","D",IF(OR('FORMATO ACTUALIZACIÓN DATOS'!BC61="X",'FORMATO ACTUALIZACIÓN DATOS'!BC64="X")=TRUE,"N","ERROR 3")),"ERROR 1"),"ERROR 4") -> ERROR 4 | BI14: 45383 | BJ14: =IF(BI15<BI12,BJ15,IF(BI12<BI15,2023,2024)) -> 2025
A15: 12 | B15: =IF(OR('FORMATO ACTUALIZACIÓN DATOS'!P21="169",'FORMATO ACTUALIZACIÓN DATOS'!P21=""),IF('FORMATO ACTUALIZACIÓN DATOS'!AM21="",0,1),1) -> 0 | C15: Municipio | D15: =IF(B15=0,CONCATENATE(" - ",C15,""),"") -> - Municipio | H15: N | O15: Paseo | P15: PS | T15: ARUBA | U15: 027 | W15: Cesar | X15: 20 | AB15: Antioquia | AC15: 05 | AD15: =CONCATENATE(AC15,"-",AE15) -> 05-14 | AE15: =IF(AB15=AB14,1+AE14,1) -> 14 | AF15: ARBOLETES | AG15: 051 | AI15: 14 | AJ15: =CONCATENATE($AA$1,"-",AI15) -> -14 | AK15: =IFERROR(VLOOKUP(AJ15,$AD$2:$AG$1120,3,0),"") | AL15: =IFERROR(VLOOKUP(AJ15,$AD$2:$AG$1120,4,0),"") | AN15: DAVIVIENDA INTERNATIONAL | AO15: DAVIVIENDA INTERNATIONAL | AQ15: 998 | AS15: 128 | AU15: Cultivo de especias y de plantas aromáticas y medicinales | AV15: 0 | AX15: 0124 | AY15: Cultivo de caña de azúcar. | BA15: Comercio al por mayor de materias primas agropecuarias; animales vivos incluye, comercio al por mayor de frutos y plantas ornamentales. | BB15: 1462002 | BE15: =IF(AND('FORMATO ACTUALIZACIÓN DATOS'!BA67="X",'FORMATO ACTUALIZACIÓN DATOS'!BC67="X")=TRUE,"ERROR",IF('FORMATO ACTUALIZACIÓN DATOS'!BA67="X","SY",IF('FORMATO ACTUALIZACIÓN DATOS'!BC67="X",""))) -> FALSE | BF15: SI SE LLENA LAS DOS OPCIONES DE PREGUNTA 3 HAY ERROR | BI15: 45748 | BJ15: =IF(BI16<BI12,BJ16,IF(BI12<BI16,2024,2025)) -> 2025
A16: 13 | B16: =IF('FORMATO ACTUALIZACIÓN DATOS'!A24="",0,1) -> 1 | C16: Correo Electrónico Reportado en el RUT | D16: =IF(B16=0,CONCATENATE(" - ",C16,""),"") | H16: Ñ | K16: TIPO DE CONTRIBUYENTE | L16: COD | O16: Transversal | P16: TV | T16: AUSTRALIA | U16: 069 | W16: Chocó | X16: 27 | AB16: Antioquia | AC16: 05 | AD16: =CONCATENATE(AC16,"-",AE16) -> 05-15 | AE16: =IF(AB16=AB15,1+AE15,1) -> 15 | AF16: ARGELIA | AG16: 055 | AI16: 15 | AJ16: =CONCATENATE($AA$1,"-",AI16) -> -15 | AK16: =IFERROR(VLOOKUP(AJ16,$AD$2:$AG$1120,3,0),"") | AL16: =IFERROR(VLOOKUP(AJ16,$AD$2:$AG$1120,4,0),"") | AN16: CITIBANK OF NEW YORK | AO16: CITIBANK OF NEW YORK | AQ16: 999 | AS16: 129 | AU16: Otros cultivos permanentes n.c.p. | AV16: 0 | AX16: 0125 | AY16: Cultivo de flor de corte. | BA16: Comercio al por mayor de materias primas agropecuarias; animales vivos incluye comercio al por mayor de materias primas agropecuarias; animales vivos y sus productos pieles en bruto, cueros, materiales, desperdicios, residuos y subproductos agropecuarios que se utilizan para producir alimentos para animales. | BB16: 1462003 | BE16: T | BF16: dos (2) o mas trabajadores= O | BG16: NO SE NECESITAN dos (2) o mas trabajadores = T | BI16: 46113 | BJ16: =IF(BI17<BI12,BJ17,IF(BI12<BI17,2025,2026)) -> 2025
A17: 14 | B17: =IF('FORMATO ACTUALIZACIÓN DATOS'!AG26="",0,1) -> 0 | C17: Teléfono 1 | D17: =IF(B17=0,CONCATENATE(" - ",C17,""),"") -> - Teléfono 1 | H17: O | K17: PERSONA JURÍDICA | L17: 1 | O17: Troncal | P17: TC | T17: AUSTRIA | U17: 072 | W17: Córdoba | X17: 23 | AB17: Antioquia | AC17: 05 | AD17: =CONCATENATE(AC17,"-",AE17) -> 05-16 | AE17: =IF(AB17=AB16,1+AE16,1) -> 16 | AF17: ARMENIA | AG17: 059 | AI17: 16 | AJ17: =CONCATENATE($AA$1,"-",AI17) -> -16 | AK17: =IFERROR(VLOOKUP(AJ17,$AD$2:$AG$1120,3,0),"") | AL17: =IFERROR(VLOOKUP(AJ17,$AD$2:$AG$1120,4,0),"") | AN17: MUFG BANK LTD. - NEW YORK | AO17: MUFG BANK LTD. - NEW YORK | AQ17: 997 | AS17: 130 | AU17: Propagación de plantas (actividades de los viveros, excepto viveros forestales) | AV17: 0 | AX17: 0126 | AY17: Cultivo de palma para aceite (palma africana) y otros frutos oleaginosos. | BA17: Comercio al por mayor de productos alimenticios, incluye ventas de frutas, legumbres y hortalizas, productos lacteos, huevos y productos de huevos, aceites y grasas comestibles, productos de confiteria, panaderia y productos farinaceos, cafe transformado, te, cacao y chocolate y especias, salsas, y otros preparados alimenticios. | BB17: 1463101 | BE17: =IF(AND('FORMATO ACTUALIZACIÓN DATOS'!BA70="X",'FORMATO ACTUALIZACIÓN DATOS'!BC70="X")=TRUE,"ERROR",IF(AND('FORMATO ACTUALIZACIÓN DATOS'!BA70="",'FORMATO ACTUALIZACIÓN DATOS'!BC70="")=TRUE,"ERROR","")) -> ERROR | BF17: SI SE LLENA O NO LAS DOS OPCIONES DE PREGUNTA 5 HAY ERROR | BI17: 46478
A18: 15 | B18: =IF('FORMATO ACTUALIZACIÓN DATOS'!AQ26="",0,1) -> 0 | C18: Teléfono 2 | D18: =IF(B18=0,CONCATENATE(" - ",C18,""),"") -> - Teléfono 2 | H18: P | K18: PERSONA NATURAL | L18: 2 | O18: Variante | P18: VT | T18: AZERBAIJAN | U18: 074 | W18: Cundinamarca | X18: 25 | AB18: Antioquia | AC18: 05 | AD18: =CONCATENATE(AC18,"-",AE18) -> 05-17 | AE18: =IF(AB18=AB17,1+AE17,1) -> 17 | AF18: BARBOSA | AG18: 079 | AI18: 17 | AJ18: =CONCATENATE($AA$1,"-",AI18) -> -17 | AK18: =IFERROR(VLOOKUP(AJ18,$AD$2:$AG$1120,3,0),"") | AL18: =IFERROR(VLOOKUP(AJ18,$AD$2:$AG$1120,4,0),"") | AN18: Itaú Corpbanca Colombia S.A | AO18: Itaú Corpbanca Colombia S.A | AQ18: 6 | AS18: 141 | AU18: Cría de ganado bovino y bufalino | AV18: 0 | AX18: 0127 | AY18: Cultivo de plantas con las que se preparan bebidas. | BA18: Comercio al por mayor de productos alimenticios, incluye el comercio al por mayor de alimentos procesados para animales domesticos. | BB18: 1463102 | BE18: =LEN(CONCATENATE('FORMATO ACTUALIZACIÓN DATOS'!BA70,'FORMATO ACTUALIZACIÓN DATOS'!BC70)) -> 0
A19: 16 | B19: =IF('FORMATO ACTUALIZACIÓN DATOS'!M31="",0,1) -> 0 | C19: Banco | D19: =IF(B19=0,CONCATENATE(" - ",C19,""),"") -> - Banco | H19: Q | O19: Vereda | P19: VRD | T19: BAHAMAS | U19: 077 | W19: Guainía | X19: 94 | AB19: Antioquia | AC19: 05 | AD19: =CONCATENATE(AC19,"-",AE19) -> 05-18 | AE19: =IF(AB19=AB18,1+AE18,1) -> 18 | AF19: BELMIRA | AG19: 086 | AI19: 18 | AJ19: =CONCATENATE($AA$1,"-",AI19) -> -18 | AK19: =IFERROR(VLOOKUP(AJ19,$AD$2:$AG$1120,3,0),"") | AL19: =IFERROR(VLOOKUP(AJ19,$AD$2:$AG$1120,4,0),"") | AN19: BANCO GENERAL TRANSITORIAS TRM | AO19: BANCO GENERAL TRANSITORIAS TRM | AQ19: 990 | AS19: 142 | AU19: Cría de caballos y otros equinos | AV19: 0 | AX19: 0128 | AY19: Cultivo de especias y de plantas aromáticas y medicinales. | BA19: Comercio al por mayor de productos textiles, productos confeccionados para uso domestico, incluye .comercio al por mayor de todo tipo de productos textiles, elaborados con fibras naturales, artificiales, sinteticas y sus mezclas, hilados, tejidos y telas en general; comercio al por mayor de lenceria y productos confeccionados para uso domestico, como: frazadas,mantas de viaje, ropa de cama, cortinas, cenefas, entre otros, y otros articulos para el hogar, confeccionados con tejidos de cualquier material textil; comercio al por mayor de materiales basicos para fabricar alfombras y tapices; comercio al por mayor de articulos de merceria: agujas, hilo para coser, entre otros. | BB19: 1464101 | BE19: =IF(AND('FORMATO ACTUALIZACIÓN DATOS'!BA70="X",'FORMATO ACTUALIZACIÓN DATOS'!BC70="X")=TRUE,"ERROR",CONCATENATE("N",BE16,BE14,BE2)) -> NTERROR 4ERROR
A20: 17 | B20: =IF('FORMATO ACTUALIZACIÓN DATOS'!Q31="",0,1) -> 0 | C20: Sucursal | D20: =IF(B20=0,CONCATENATE(" - ",C20,""),"") -> - Sucursal | H20: R | T20: BAHREIN | U20: 080 | W20: Guaviare | X20: 95 | AB20: Antioquia | AC20: 05 | AD20: =CONCATENATE(AC20,"-",AE20) -> 05-19 | AE20: =IF(AB20=AB19,1+AE19,1) -> 19 | AF20: BELLO | AG20: 088 | AI20: 19 | AJ20: =CONCATENATE($AA$1,"-",AI20) -> -19 | AK20: =IFERROR(VLOOKUP(AJ20,$AD$2:$AG$1120,3,0),"") | AL20: =IFERROR(VLOOKUP(AJ20,$AD$2:$AG$1120,4,0),"") | AN20: Bancoldex | AO20: Bancoldex | AQ20: 800 | AS20: 143 | AU20: Cría de ovejas y cabras | AV20: 0 | AX20: 0129 | AY20: Otros cultivos permanentes n.c.p. | BA20: Comercio al por mayor de prendas de vestir, incluye todo tipo de prendas de vestir (incluso las prendas de vestir de cuero), para hombres, mujeres, niños y bebes ropa interior, de dormir, de etiqueta, de trabajo, para practicar deportes, entre otros y de todo tipo de accesorios para prendas de vestir y de articulos elaborados en piel | BB20: 1464201
A21: 18 | B21: =IF('FORMATO ACTUALIZACIÓN DATOS'!AE31="",0,1) -> 0 | C21: Tipo Cuenta | D21: =IF(B21=0,CONCATENATE(" - ",C21,""),"") -> - Tipo Cuenta | H21: S | K21: REGIMEN | L21: SIGLA | T21: BANGLADESH | U21: 081 | W21: Huila | X21: 41 | AB21: Antioquia | AC21: 05 | AD21: =CONCATENATE(AC21,"-",AE21) -> 05-20 | AE21: =IF(AB21=AB20,1+AE20,1) -> 20 | AF21: BETANIA | AG21: 091 | AI21: 20 | AJ21: =CONCATENATE($AA$1,"-",AI21) -> -20 | AK21: =IFERROR(VLOOKUP(AJ21,$AD$2:$AG$1120,3,0),"") | AL21: =IFERROR(VLOOKUP(AJ21,$AD$2:$AG$1120,4,0),"") | AN21: SIN CUENTA - EFECTIVO | AO21: SIN CUENTA - EFECTIVO | AQ21: CJA | AS21: 144 | AU21: Cría de ganado porcino | AV21: 0 | AX21: 0130 | AY21: Propagación de plantas (actividades de los viveros, excepto viveros forestales). | BA21: Comercio al por mayor de calzado de cualquier material y para todo uso y partes para calzado. | BB21: 1464301 | BE21: =IF(OR(BE18=2,BE18=0),"REVISE SU INFORMACIÓN TRIBUTARIA",IF(BE15="SY",CONCATENATE("N",BE15,BG23),CONCATENATE("N",BE15,BE2))) -> REVISE SU INFORMACIÓN TRIBUTARIA
A22: 19 | B22: =IF('FORMATO ACTUALIZACIÓN DATOS'!AN32="",0,1) -> 0 | C22: No Cuenta Bancaria | D22: =IF(B22=0,CONCATENATE(" - ",C22,""),"") -> - No Cuenta Bancaria | H22: T | K22: RESPONSABLE IVA | L22: RC | O22: FORMATO SED - CON ANEXOS | T22: BARBADOS | U22: 083 | W22: La Guajira | X22: 44 | AB22: Antioquia | AC22: 05 | AD22: =CONCATENATE(AC22,"-",AE22) -> 05-21 | AE22: =IF(AB22=AB21,1+AE21,1) -> 21 | AF22: BETULIA | AG22: 093 | AI22: 21 | AJ22: =CONCATENATE($AA$1,"-",AI22) -> -21 | AK22: =IFERROR(VLOOKUP(AJ22,$AD$2:$AG$1120,3,0),"") | AL22: =IFERROR(VLOOKUP(AJ22,$AD$2:$AG$1120,4,0),"") | AN22: Banco W S.A | AO22: Banco W S.A | AQ22: 53 | AS22: 145 | AU22: Cría de aves de corral | AV22: 0 | AX22: 0141 | AY22: Cría de ganado bovino y bufalino. | BA22: Comercio al por mayor de aparatos y equipo de uso domestico, incluye electrodomesticos y gas domestico, refrigeradores, lavadoras, maquinas para secar ropa, maquinas lavaplatos, aspiradoras, aparatos para calefaccion, hornos, asadores, estufas, calentadores, entre otros, para uso domestico, amplificadores, consolas, parlantes, equipos de reproduccion de sonido, radio television y comunicaciones, discos, cintas, CD, DVD, Blu-ray Disc y demas dispositivos de almacenamiento de audio y de video grabados | BB22: 1464401 | BE22: =IF(AND(BE15="",BE17=""),BE19,BE21) -> REVISE SU INFORMACIÓN TRIBUTARIA
A23: 20 | B23: =IF('FORMATO ACTUALIZACIÓN DATOS'!A40="",0,1) -> 0 | C23: Actividad Económica RUT | D23: =IF(B23=0,CONCATENATE(" - ",C23,""),"") -> - Actividad Económica RUT | H23: U | K23: NO RESPONSABLE IVA | L23: RS | T23: BELGICA | U23: 087 | W23: Magdalena | X23: 47 | AB23: Antioquia | AC23: 05 | AD23: =CONCATENATE(AC23,"-",AE23) -> 05-22 | AE23: =IF(AB23=AB22,1+AE22,1) -> 22 | AF23: CIUDAD BOLÍVAR | AG23: 101 | AI23: 22 | AJ23: =CONCATENATE($AA$1,"-",AI23) -> -22 | AK23: =IFERROR(VLOOKUP(AJ23,$AD$2:$AG$1120,3,0),"") | AL23: =IFERROR(VLOOKUP(AJ23,$AD$2:$AG$1120,4,0),"") | AN23: Banco de las Microfinanzas - Bancamia | AO23: Banco de las Microfinanzas - Bancamia | AQ23: 59 | AS23: 149 | AU23: Cría de otros animales n.c.p. | AV23: 0 | AX23: 0142 | AY23: Cría de caballos y otros equinos. | BA23: Comercio al por mayor de aparatos y equipo de uso domestico, incluye el comercio al por mayor de articulos y utensilios de uso domestico tales como cubiertos, vajillas, articulos de iluminacion, cristaleria, articulos de ceramica y utensilios de madera, de mimbre y de corcho para mesa, tocador, cocina o similares | BB23: 1464402 | BE23: =_xlfn.CONCAT(IF(LEN(BE22)>4,"REVISE SU INFORMACIÓN TRIBUTARIA",BE22),BE25) -> REVISE SU INFORMACIÓN TRIBUTARIA | BG23: =IF('FORMATO ACTUALIZACIÓN DATOS'!AU39="RESPONSABLE IVA","M",IF('FORMATO ACTUALIZACIÓN DATOS'!AU39="NO RESPONSABLE IVA","S","ERROR")) -> ERROR
A24: 21 | B24: =IF('FORMATO ACTUALIZACIÓN DATOS'!A40="",0,IF('FORMATO ACTUALIZACIÓN DATOS'!F39="Actividad economica no existe - por favor verificar",0,1)) -> 0 | C24: Actividad económica RUT NO existe - por favor verificar | D24: =IF(B24=0,CONCATENATE(" - ",C24,""),"") -> - Actividad económica RUT NO existe - por favor verificar | H24: V | T24: BELICE | U24: 088 | W24: Meta | X24: 50 | AB24: Antioquia | AC24: 05 | AD24: =CONCATENATE(AC24,"-",AE24) -> 05-23 | AE24: =IF(AB24=AB23,1+AE23,1) -> 23 | AF24: BRICEÑO | AG24: 107 | AI24: 23 | AJ24: =CONCATENATE($AA$1,"-",AI24) -> -23 | AK24: =IFERROR(VLOOKUP(AJ24,$AD$2:$AG$1120,3,0),"") | AL24: =IFERROR(VLOOKUP(AJ24,$AD$2:$AG$1120,4,0),"") | AN24: Banco Pichincha | AO24: Banco Pichincha | AQ24: 60 | AS24: 150 | AU24: Explotación primaria mixta (agrícola y pecuaria) | AV24: 0 | AX24: 0143 | AY24: Cría de ovejas y cabras. | BA24: Comercio al por mayor de productos farmaceuticos, medicinales, cosmeticos y de tocador, incluye productos farmaceuticos y medicinales, productos botanicos, articulos de perfumeria, cosmeticos y jabones de tocador y jabones detergentes, ademas de los preparados organicos tensoactivos envase y empaque de dichos productos, cuando se realiza por cuenta propia | BB24: 1464501
A25: 22 | B25: =IF('FORMATO ACTUALIZACIÓN DATOS'!X40="",0,1) -> 0 | C25: Actividad Económica RIT | D25: =IF(B25=0,CONCATENATE(" - ",C25,""),"") -> - Actividad Económica RIT | H25: W | K25: VALOR DIA | L25: VALOR | T25: BELORUS | U25: 091 | W25: Nariño | X25: 52 | AB25: Antioquia | AC25: 05 | AD25: =CONCATENATE(AC25,"-",AE25) -> 05-24 | AE25: =IF(AB25=AB24,1+AE24,1) -> 24 | AF25: BURITICÁ | AG25: 113 | AI25: 24 | AJ25: =CONCATENATE($AA$1,"-",AI25) -> -24 | AK25: =IFERROR(VLOOKUP(AJ25,$AD$2:$AG$1120,3,0),"") | AL25: =IFERROR(VLOOKUP(AJ25,$AD$2:$AG$1120,4,0),"") | AN25: Bancoomeva | AO25: Bancoomeva | AQ25: 61 | AS25: 161 | AT25: 304 | AU25: Actividades de apoyo a la agricultura | AV25: 9.66 | AX25: 0144 | AY25: Cría de ganado porcino. | BA25: Comercio al por mayor de productos farmaceuticos, medicinales, cosmeticos y de tocador, incluye el comercio al por mayor de articulos ortesicos y protesicos, drogas veterinarias y articulos para uso veterinario; envase y empaque de dichos productos, cuando se realiza por cuenta propia. | BB25: 1464502 | BE25: =IF('FORMATO ACTUALIZACIÓN DATOS'!Q18="X"," /PENSIONADO","")
A26: 23 | B26: =IF('FORMATO ACTUALIZACIÓN DATOS'!X40="",0,IF('FORMATO ACTUALIZACIÓN DATOS'!AD39="Actividad economica no existe - por favor verificar",0,1)) -> 0 | C26: Actividad economica RIT NO existe - por favor verificar | D26: =IF(B26=0,CONCATENATE(" - ",C26,""),"") -> - Actividad economica RIT NO existe - por favor verificar | H26: X | K26: VALOR DE CONTRATO | L26: ='FORMATO ACTUALIZACIÓN DATOS'!K46 -> 0 | T26: BENIN | U26: 229 | W26: Norte de Santander | X26: 54 | AB26: Antioquia | AC26: 05 | AD26: =CONCATENATE(AC26,"-",AE26) -> 05-25 | AE26: =IF(AB26=AB25,1+AE25,1) -> 25 | AF26: CÁCERES | AG26: 120 | AI26: 25 | AJ26: =CONCATENATE($AA$1,"-",AI26) -> -25 | AK26: =IFERROR(VLOOKUP(AJ26,$AD$2:$AG$1120,3,0),"") | AL26: =IFERROR(VLOOKUP(AJ26,$AD$2:$AG$1120,4,0),"") | AN26: Confiar Cooperativa Financiera | AO26: Confiar Cooperativa Financiera | AQ26: 292 | AS26: 162 | AT26: 304 | AU26: Actividades de apoyo a la ganadería | AV26: 9.66 | AX26: 0145 | AY26: Cría de aves de corral. | BA26: Comercio al por mayor de otros utensilios domesticos ncp, incluye: muebles colchones, somieres y articulos de uso domestico ncp, bicicletas sus partes y accesorios, material de limpieza y pulido (desodorizadores de ambientes, ceras artificiales, betunes, entre otros), articulos fotograficos y opticos (ej: gafas de sol, binoculares, lupas), juegos, juguetes, articulos de piñateria, relojes y articulos de joyeria, articulos deportivos, articulos de viaje, de cuero natural y de imitacion de cuero, maletas, bolsos de mano, carteras, y articulos de talabarteria y guarnicioneria (sillas de montar), paraguas, instrumentos musicales, articulos de papeleria, libros, revistas y periodicos entre otros | BB26: 1464901
A27: 24 | B27: =IF('FORMATO ACTUALIZACIÓN DATOS'!AU39="",0,1) -> 0 | C27: Régimen | D27: =IF(B27=0,CONCATENATE(" - ",C27,""),"") -> - Régimen | H27: Y | K27: VALOR MENSUAL | L27: ='FORMATO ACTUALIZACIÓN DATOS'!A50 -> 0 | T27: BERMUDAS | U27: 090 | W27: Putumayo | X27: 86 | AB27: Antioquia | AC27: 05 | AD27: =CONCATENATE(AC27,"-",AE27) -> 05-26 | AE27: =IF(AB27=AB26,1+AE26,1) -> 26 | AF27: CAICEDO | AG27: 125 | AI27: 26 | AJ27: =CONCATENATE($AA$1,"-",AI27) -> -26 | AK27: =IFERROR(VLOOKUP(AJ27,$AD$2:$AG$1120,3,0),"") | AL27: =IFERROR(VLOOKUP(AJ27,$AD$2:$AG$1120,4,0),"") | AN27: Banco Mibanco S.A. | AO27: Banco Mibanco S.A. | AQ27: 67 | AS27: 163 | AU27: Actividades posteriores a la cosecha | AV27: 0 | AX27: 0149 | AY27: Cría de otros animales n.c.p. | BA27: Comercio al por mayor de computadores, equipo periferico y programas de informatica | BB27: 1465101
A28: 25 | B28: =IF('FORMATO ACTUALIZACIÓN DATOS'!A46="",0,1) -> 0 | C28: No Contrato | D28: =IF(B28=0,CONCATENATE(" - ",C28,""),"") -> - No Contrato | H28: Z | K28: DIAS | L28: =IFERROR(((L26*30)/L27)," ") | T28: BIRMANIA (MYANMAR) | U28: 093 | W28: Quindio | X28: 63 | AB28: Antioquia | AC28: 05 | AD28: =CONCATENATE(AC28,"-",AE28) -> 05-27 | AE28: =IF(AB28=AB27,1+AE27,1) -> 27 | AF28: CALDAS | AG28: 129 | AI28: 27 | AJ28: =CONCATENATE($AA$1,"-",AI28) -> -27 | AK28: =IFERROR(VLOOKUP(AJ28,$AD$2:$AG$1120,3,0),"") | AL28: =IFERROR(VLOOKUP(AJ28,$AD$2:$AG$1120,4,0),"") | AN28: Banco Cooperativo Coopcentral | AO28: Banco Cooperativo Coopcentral | AQ28: 66 | AS28: 164 | AT28: 304 | AU28: Tratamiento de semillas para propagación | AV28: 9.66 | AX28: 0150 | AY28: Explotación mixta (agrícola y pecuaria). | BA28: Comercio al por mayor de otros tipos de maquinaria y equipo ncp, incluye el comercio al por mayor de equipo, articulos e instrumentos medicos, quirurgicos y para laboratorio, muebles, maquinaria y equipo de oficina excepto computadores y equipo periferico, instrumentos y equipo de medicion, partes, piezas y accesorios | BB28: 1465901
A29: 26 | B29: =IF('FORMATO ACTUALIZACIÓN DATOS'!F47="",0,1) -> 0 | C29: Año Contrato | D29: =IF(B29=0,CONCATENATE(" - ",C29,""),"") -> - Año Contrato | T29: BOLIVIA | U29: 097 | W29: Risaralda | X29: 66 | AB29: Antioquia | AC29: 05 | AD29: =CONCATENATE(AC29,"-",AE29) -> 05-28 | AE29: =IF(AB29=AB28,1+AE28,1) -> 28 | AF29: CAMPAMENTO | AG29: 134 | AI29: 28 | AJ29: =CONCATENATE($AA$1,"-",AI29) -> -28 | AK29: =IFERROR(VLOOKUP(AJ29,$AD$2:$AG$1120,3,0),"") | AL29: =IFERROR(VLOOKUP(AJ29,$AD$2:$AG$1120,4,0),"") | AN29: Banco Finandina S.A | AO29: Banco Finandina S.A | AQ29: 63 | AS29: 170 | AU29: Caza ordinaria y mediante trampas y actividades de servicios conexas | AV29: 0 | AX29: 0161 | AY29: Actividades de apoyo a la agricultura. | BA29: Comercio al por mayor de combustibles solidos, liquidos, gaseosos y productos conexos, incluye comercio al por mayor de grasas, lubricantes y aceites. | BB29: 1466101
A30: 27 | B30: =IF('FORMATO ACTUALIZACIÓN DATOS'!K46="",0,1) -> 0 | C30: Valor Total del Contrato | D30: =IF(B30=0,CONCATENATE(" - ",C30,""),"") -> - Valor Total del Contrato | T30: BOSNIA-HERZEGOVINA | U30: 029 | W30: Santander | X30: 68 | AB30: Antioquia | AC30: 05 | AD30: =CONCATENATE(AC30,"-",AE30) -> 05-29 | AE30: =IF(AB30=AB29,1+AE29,1) -> 29 | AF30: CAÑASGORDAS | AG30: 138 | AI30: 29 | AJ30: =CONCATENATE($AA$1,"-",AI30) -> -29 | AK30: =IFERROR(VLOOKUP(AJ30,$AD$2:$AG$1120,3,0),"") | AL30: =IFERROR(VLOOKUP(AJ30,$AD$2:$AG$1120,4,0),"") | AN30: Banco Falabella S.A | AO30: Banco Falabella S.A | AQ30: 62 | AS30: 210 | AU30: Silvicultura y otras actividades forestales | AV30: 0 | AX30: 0162 | AY30: Actividades de apoyo a la ganadería. | BA30: Comercio al por mayor de materiales de construccion, articulos de ferreteria, pinturas sin mezclado), productos de vidrio, equipo y materiales de fontaneria y calefaccion, incluye comercio al por mayor de pinturas y barnices (sin mezclado) | BB30: 1466301
A31: 28 | B31: =IF('FORMATO ACTUALIZACIÓN DATOS'!A50="",0,1) -> 0 | C31: Valor Pago Mensual según Contrato | D31: =IF(B31=0,CONCATENATE(" - ",C31,""),"") -> - Valor Pago Mensual según Contrato | K31: SI | T31: BOTSWANA | U31: 101 | W31: Sucre | X31: 70 | AB31: Antioquia | AC31: 05 | AD31: =CONCATENATE(AC31,"-",AE31) -> 05-30 | AE31: =IF(AB31=AB30,1+AE30,1) -> 30 | AF31: CARACOLÍ | AG31: 142 | AI31: 30 | AJ31: =CONCATENATE($AA$1,"-",AI31) -> -30 | AK31: =IFERROR(VLOOKUP(AJ31,$AD$2:$AG$1120,3,0),"") | AL31: =IFERROR(VLOOKUP(AJ31,$AD$2:$AG$1120,4,0),"") | AN31: Coltefinanciera S.A | AO31: Coltefinanciera S.A | AQ31: 370 | AS31: 220 | AU31: Extracción de madera | AV31: 0 | AX31: 0163 | AY31: Actividades posteriores a la cosecha. | BA31: Comercio al por mayor de productos quimicos basicos, cauchos y plasticos en formas primarias y productos quimicos de uso agropecuario, incluye materiales colorantes, plastico incluso el plastico celular (espuma), caucho en formas primarias, el comercio al por mayor de sustancias quimicas de uso industrial como: anilina, tinta de imprenta, aceites esenciales, parafina, aromas y aromatizantes, el comercio al por mayor de abonos y derivados del almidon, colorantes, resinas sinteticas | BB31: 1466401
A32: 29 | B32: =IF('FORMATO ACTUALIZACIÓN DATOS'!AC46="",0,1) -> 0 | C32: Fecha Acta de Inicio | D32: =IF(B32=0,CONCATENATE(" - ",C32,""),"") -> - Fecha Acta de Inicio | K32: NO | T32: BRASIL | U32: 105 | W32: Tolima | X32: 73 | AB32: Antioquia | AC32: 05 | AD32: =CONCATENATE(AC32,"-",AE32) -> 05-31 | AE32: =IF(AB32=AB31,1+AE31,1) -> 31 | AF32: CARAMANTA | AG32: 145 | AI32: 31 | AJ32: =CONCATENATE($AA$1,"-",AI32) -> -31 | AK32: =IFERROR(VLOOKUP(AJ32,$AD$2:$AG$1120,3,0),"") | AL32: =IFERROR(VLOOKUP(AJ32,$AD$2:$AG$1120,4,0),"") | AN32: Cooperativa Financiera de Antioquia | AO32: Cooperativa Financiera de Antioquia | AQ32: 283 | AS32: 230 | AU32: Recolección de productos forestales diferentes a la madera | AV32: 0 | AX32: 0164 | AY32: Tratamiento de semillas para propagación. | BA32: Comercio al por mayor de otros productos n.c.p., incluye el comercio al por mayor de fibras textiles, papel a granel y piedras preciosas, suministros de embalaje. | BB32: 1466901
A33: 30 | B33: =IF('FORMATO ACTUALIZACIÓN DATOS'!AN46="",0,1) -> 0 | C33: Fecha terminación Contrato | D33: =IF(B33=0,CONCATENATE(" - ",C33,""),"") -> - Fecha terminación Contrato | T33: BRUNEI DARUSSALAM | U33: 108 | W33: Valle del Cauca | X33: 76 | AB33: Antioquia | AC33: 05 | AD33: =CONCATENATE(AC33,"-",AE33) -> 05-32 | AE33: =IF(AB33=AB32,1+AE32,1) -> 32 | AF33: CAREPA | AG33: 147 | AI33: 32 | AJ33: =CONCATENATE($AA$1,"-",AI33) -> -32 | AK33: =IFERROR(VLOOKUP(AJ33,$AD$2:$AG$1120,3,0),"") | AL33: =IFERROR(VLOOKUP(AJ33,$AD$2:$AG$1120,4,0),"") | AN33: Cootrafa Cooperativa Financiera | AO33: Cootrafa Cooperativa Financiera | AQ33: 289 | AS33: 240 | AT33: 304 | AU33: Servicios de apoyo a la silvicultura | AV33: 9.66 | AX33: 0170 | AY33: Caza ordinaria y mediante trampas y actividades de servicios conexas. | BA33: Comercio al por mayor no especializado, incluye el comercio de una variedad de productos sin ninguna especializacion en particular. | BB33: 1469001
A34: 30.1 | B34: =IF('FORMATO ACTUALIZACIÓN DATOS'!V50="",0,1) -> 0 | C34: VIGENCIA FUTURA | D34: =IF(B34=0,CONCATENATE(" - ",C34,""),"") -> - VIGENCIA FUTURA | T34: BULGARIA | U34: 111 | W34: Vaupés | X34: 97 | AB34: Antioquia | AC34: 05 | AD34: =CONCATENATE(AC34,"-",AE34) -> 05-33 | AE34: =IF(AB34=AB33,1+AE33,1) -> 33 | AF34: EL CARMEN DE VIBORAL | AG34: 148 | AI34: 33 | AJ34: =CONCATENATE($AA$1,"-",AI34) -> -33 | AK34: =IFERROR(VLOOKUP(AJ34,$AD$2:$AG$1120,3,0),"") | AL34: =IFERROR(VLOOKUP(AJ34,$AD$2:$AG$1120,4,0),"") | AN34: Financiera Juriscoop S.A. Compañía Financiamiento | AO34: Financiera Juriscoop S.A. Compañía Financiamiento | AQ34: 121 | AS34: 311 | AU34: Pesca marítima | AV34: 0 | AX34: 0210 | AY34: Silvicultura y otras actividades forestales. | BA34: Comercio al por menor en establecimientos no especializados con surtido compuesto principalmente por alimentos, bebidas o tabaco, incluye establecimientos no especializados de comercio al por menor de productos cuyo surtido esta compuesto principalmente de alimentos (viveres en general) bebidas o tabaco, cosmeticos, vestuario | BB34: 1471101
A35: 31 | B35: =IF('FORMATO ACTUALIZACIÓN DATOS'!AY46="",0,1) -> 0 | C35: Cesión | D35: =IF(B35=0,CONCATENATE(" - ",C35,""),"") -> - Cesión | K35: Área Funcional de la SED | L35: CODIGO | T35: BURKINA FASSO | U35: 031 | W35: Vichada | X35: 99 | AB35: Antioquia | AC35: 05 | AD35: =CONCATENATE(AC35,"-",AE35) -> 05-34 | AE35: =IF(AB35=AB34,1+AE34,1) -> 34 | AF35: CAROLINA | AG35: 150 | AI35: 34 | AJ35: =CONCATENATE($AA$1,"-",AI35) -> -34 | AK35: =IFERROR(VLOOKUP(AJ35,$AD$2:$AG$1120,3,0),"") | AL35: =IFERROR(VLOOKUP(AJ35,$AD$2:$AG$1120,4,0),"") | AN35: Nequi | AO35: Nequi | AQ35: 507 | AS35: 312 | AU35: Pesca de agua dulce | AV35: 0 | AX35: 0220 | AY35: Extracción de madera. | BA35: Comercio al por menor en establecimientos no especializados, con surtido compuesto principalmente por alimentos, bebidas o tabaco, incluye expendio de otras mercancias para consumo de los hogares tales, electrodomesticos, muebles, articulos de ferreteria, entre otros | BB35: 1471102
A36: 32 | B36: =IF('FORMATO ACTUALIZACIÓN DATOS'!A53="",0,1) -> 0 | C36: Área Funcional de la SED | D36: =IF(B36=0,CONCATENATE(" - ",C36,""),"") -> - Área Funcional de la SED | K36: Despacho Del Secretario | L36: 1000 | T36: BURUNDI | U36: 115 | W36: Otro | AB36: Antioquia | AC36: 05 | AD36: =CONCATENATE(AC36,"-",AE36) -> 05-35 | AE36: =IF(AB36=AB35,1+AE35,1) -> 35 | AF36: CAUCASIA | AG36: 154 | AI36: 35 | AJ36: =CONCATENATE($AA$1,"-",AI36) -> -35 | AK36: =IFERROR(VLOOKUP(AJ36,$AD$2:$AG$1120,3,0),"") | AL36: =IFERROR(VLOOKUP(AJ36,$AD$2:$AG$1120,4,0),"") | AN36: Banco Multibank S.A. | AO36: Banco Multibank S.A. | AQ36: 64 | AS36: 321 | AU36: Acuicultura marítima | AV36: 0 | AX36: 0230 | AY36: Recolección de productos forestales diferentes a la madera. | BA36: Comercio al por menor en establecimientos no especializados, con surtido compuesto principalmente por productos diferentes de alimentos (viveres en general), bebidas y tabaco; incluye los establecimientos denominados bazares, cacharrerias, quincallerias, con surtido diverso de mercancias tales como cosmeticos, articulos escolares, mercerias, tarjetas, jugueteria, fantasias, entre otros | BB36: 1471901
A37: 33 | B37: =IF('FORMATO ACTUALIZACIÓN DATOS'!J53="",0,1) -> 0 | C37: Nombre Interventor Contrato | D37: =IF(B37=0,CONCATENATE(" - ",C37,""),"") -> - Nombre Interventor Contrato | K37: Oficina Asesora de Planeación | L37: 1100 | T37: BUTAN | U37: 119 | AB37: Antioquia | AC37: 05 | AD37: =CONCATENATE(AC37,"-",AE37) -> 05-36 | AE37: =IF(AB37=AB36,1+AE36,1) -> 36 | AF37: CHIGORODÓ | AG37: 172 | AI37: 36 | AJ37: =CONCATENATE($AA$1,"-",AI37) -> -36 | AK37: =IFERROR(VLOOKUP(AJ37,$AD$2:$AG$1120,3,0),"") | AL37: =IFERROR(VLOOKUP(AJ37,$AD$2:$AG$1120,4,0),"") | AN37: Banco Serfinanza S.A | AO37: Banco Serfinanza S.A | AQ37: 69 | AS37: 322 | AU37: Acuicultura de agua dulce | AV37: 0 | AX37: 0240 | AY37: Servicios de apoyo a la silvicultura. | BA37: Comercio al por menor de leche, productos lacteos y huevos en establecimientos especializados, incluye comercio al por menor de leche, productos lacteos (mantequilla, quesos, cuajadas, cremas de leche, yogur) y huevos, sin autotransporte | BB37: 1472201
